Workbook
Name Aguacate: Caracteristicas!$A$39
Name AMAZONAS: departamento!$F$3:$F$13
Name ANTIOQUIA: departamento!$G$3:$G$127
Name ARAUCA: departamento!$H$3:$H$9
Name ATLÁNTICO: departamento!$I$3:$I$25
Name BOLÍVAR: departamento!$J$3:$J$48
Name BOYACÁ: departamento!$K$3:$K$125
Name Cacao: Caracteristicas!$B$39
Name Café: Caracteristicas!$C$39
Name CALDAS: departamento!$L$3:$L$29
Name Caña_Azucar: Caracteristicas!$L$39:$L$41
Name CAQUETÁ: departamento!$M$3:$M$18
Name CASANARE: departamento!$N$3:$N$21
Name CAUCA: departamento!$O$3:$O$44
Name CESAR: departamento!$P$3:$P$27
Name CHOCÓ: departamento!$Q$3:$Q$33
Name CÓRDOBA: departamento!$R$3:$R$32
Name CUNDINAMARCA: departamento!$S$3:$S$118
Name Eucalipto: Caracteristicas!$D$39
Name GUAINÍA: departamento!$T$3:$T$10
Name GUAVIARE: departamento!$U$3:$U$6
Name HUILA: departamento!$V$3:$V$39
Name Limón: Caracteristicas!$E$39:$E$41
Name MAGDALENA: departamento!$X$3:$X$32
Name Mandarina: Caracteristicas!$F$39
Name Mango: Caracteristicas!$G$39
Name META: departamento!$Y$3:$Y$31
Name Naranja: Caracteristicas!$K$39:$K$40
Name NARIÑO: departamento!$Z$3:$Z$66
Name NORTE_DE_SANTANDER: departamento!$AA$3:$AA$42
Name Palma_Aceite: Caracteristicas!$H$39:$H$40
Name Plátano: Caracteristicas!$I$39
Name PUTUMAYO: departamento!$AB$3:$AB$15
Name QUINDÍO: departamento!$AC$3:$AC$14
Name RISARALDA: departamento!$AD$3:$AD$16
Name SANTANDER: departamento!$AE$3:$AE$89
Name SUCRE: departamento!$AF$3:$AF$28
Name TOLIMA: departamento!$AG$3:$AG$49
Name VALLE_DEL_CAUCA: departamento!$AH$3:$AH$44
Name VICHADA: departamento!$AJ$3:$AJ$6

Sheet Instrucciones
A1: MANUAL DE USO — AVALÚO DE CULTIVO (Res. 620/2008)
A2: Herramienta para perímetros agrícolas — Cálculo de valor justo del cultivo y banda de negociación
A4: CÓDIGO DE COLORES
A5: Color | B5: Significado | C5: Acción del usuario
A6: AZUL | B6: Valores editables | C6: Cambie el valor según el caso (cultivo, edad, precio, etc.)
A7: NEGRO | B7: Fórmula calculada | C7: No modificar — se actualiza automáticamente
A8: VERDE | B8: Enlace a otra hoja del libro | C8: No modificar — referencia interna
A9: ROJO | B9: Resultado clave del avalúo | C9: Lectura — valor que arroja la herramienta
A10: AMARILLO | B10: Celda clave que requiere atención | C10: Revisar antes de tomar el valor
A12: ESTRUCTURA DEL LIBRO — ¿QUÉ HACE CADA HOJA?
A13: # | B13: Hoja | C13: Función | D13: Tipo
A14: 1 | B14: Formulario | C14: Punto de entrada — cultivo, edad, departamento, municipio, precio de venta, área | D14: ENTRADA
A15: 2 | B15: PERITO | C15: Datos del perito y entidad emisora del avalúo | D15: ENTRADA
A16: 3 | B16: Entradas_Tasas | C16: Selección del método de tasa de descuento (DTF+Prima, CAPM, Finagro, WACC) | D16: ENTRADA
A17: 4 | B17: Entradas_calculos | C17: Variables clave consolidadas: edad, precio, tasa, costos por año de etapa improductiva | D17: CÁLCULO
A18: 5 | B18: Calculos_generales | C18: Análisis financiero consolidado en la misma hoja: TIR del proyecto (Q3), Relación Costo/Beneficio (Q4) y Punto de equilibrio (Q5) | D18: ANÁLISIS
A19: 6 | B19: Amortización | C19: Tabla de amortización de la inversión inicial | D19: CÁLCULO
A20: 7 | B20: calculo_etapa_vegetativa | C20: Costos capitalizados de la siembra hasta la edad actual del cultivo | D20: CÁLCULO
A21: 8 | B21: Calculo_etapa_productiva | C21: Flujos de caja proyectados año por año (rendimiento, ingreso, costo, flujo neto) | D21: CÁLCULO
A22: 9 | B22: escenario de negociación | C22: TABLERO PRINCIPAL — valor del cultivo, banda de negociación y argumentos | D22: RESULTADO
A23: 10 | B23: Resumen_Departamento | C23: Resumen agregado por departamento | D23: RESULTADO
A24: 11 | B24: PreciosRef. por Mercado / Tabla_Costos_Insumos / departamento / Base_datActividades_priorFIN / Caracteristicas / Caracteristicas_agronomicas / Rendimientos estandar_ / Tiempos de cosecha_ / mecanización_ pendiente / Jornalesdeppto / Limites_agroecologicos | C24: Bases de datos de referencia (precios, jornales, rendimientos, características) | D24: DATOS
A26: FLUJO DE TRABAJO — PASO A PASO
A27: Paso | B27: Acción | C27: Dónde | D27: Resultado
A28: 1 | B28: Diligenciar datos del cultivo: especie, edad actual, departamento, municipio, precio venta y área | C28: Formulario | D28: Parámetros base cargados
A29: 2 | B29: en este espacio es cuando el perito tenga una densidad diferente a la densidad usada lo cual trae como consecuencia que se deba hacer calculo de jornales a partir de los tiempos y movimientos encontrados en la Base_datActividades_priorFIN columna R | C29: PERITO | D29: Identificación del avalúo
A30: 3 | B30: Seleccionar método de tasa de descuento escribiendo el nombre exacto (DTF + Prima de Riesgo, CAPM, Finagro o WACC) en la celda C57 | C30: Entradas_Tasas → C57 | D30: Tasa activa definida
A31: 4 | B31: Revisar cálculos automáticos (no editar) | C31: Calculo_etapa_productiva, calculo_etapa_vegetativa, Calculos_generales, Amortización | D31: Flujos y costos calculados
A32: 5 | B32: Consultar el VALOR DEL CULTIVO RECOMENDADO en el bloque resumen | C32: escenario de negociación → C28 | D32: Precio sugerido $/ha
A33: 6 | B33: Comparar contra TECHO, PISO, REFERENCIA Finagro y oferta agresiva | C33: escenario de negociación → C26:E30 | D33: Banda de negociación
A34: 7 | B34: Argumentar con base en los textos técnicos del tablero | C34: escenario de negociación → C33:E34 | D34: Argumentos negociadores
A36: CONCEPTOS CLAVE
A37: Concepto | B37: Definición
A38: VPN remanente | B38: Valor presente neto de los flujos futuros desde la edad actual hasta el fin de la vida útil del cultivo
A39: Costo de reposición | B39: Lo que costaría hoy reconstruir el cultivo desde cero hasta la edad actual (capitalizado a la tasa de descuento)
A40: TECHO | B40: Precio máximo del vendedor (escenario favorable: tasa Res. 620 base)
A41: PISO | B41: Precio mínimo del vendedor: lo que costó construir el cultivo + lucro cesante
A42: OFERTA RECOMENDADA | B42: Precio justo a tasa privada (18%) — lo que arroja el aplicativo como valor recomendado del cultivo
A43: OFERTA AGRESIVA | B43: Precio de apertura del comprador (tasa 20%) — punto de partida táctico
A44: TIR sembrador | B44: Rentabilidad del proyecto si lo lleva hasta el final de la vida útil
...

Sheet Formulario
A1: SUBDIRECCIÓN AVALÚOS | K1: Versión 0.3
A2: AVALÚOS COMERCIALES CULTIVOS AGRICOLAS
A3: FORMULARIO RECOLECCIÓN DATOS CULTIVOS
A5: 1. DATOS GENERALES
A7: Departamento | B7: CAUCA | E7: Municipio | F7: AMALFI | I7: Vereda | M7: VERIFICACIÓN COBERTURA CULTIVO × DEPARTAMENTO
M8: Insumos esperados: | P8: =COUNTIFS(Base_datActividades_priorFIN!A17:A1215,A22,Base_datActividades_priorFIN!B17:B1215,B22,Base_datActividades_priorFIN!K17:K1215,"<>") -> 54
M9: Insumos con precio: | P9: =COUNTIFS(Base_datActividades_priorFIN!A17:A1215,A22,Base_datActividades_priorFIN!B17:B1215,B22,Base_datActividades_priorFIN!K17:K1215,"<>",Base_datActividades_priorFIN!N17:N1215,">0") -> 54
M10: % Cobertura: | P10: =IFERROR(P9/P8,0) -> 1
A11: 2. CARACTERISTICAS AGROLOGICAS | M11: Estado: | N11: =IF(P8=0,"⚠ Cultivo sin datos",IF(P10>=0.999,"✓ COBERTURA COMPLETA",IF(P10>=0.8,"⚠ Cobertura parcial",IF(P10>0,"✗ Cobertura insuficiente","✗ Sin cobertura en este depto")))) -> ✓ COBERTURA COMPLETA
M12: Detalle: | N12: =IF(P8=0,"Verifica cultivo+variedad en A22:B22",IF(P10>=0.999,"Todos los "&P8&" insumos tienen precio en "&B7,IF(P9>0,"Faltan "&(P8-P9)&" de "&P8&" insumos con precio en "&B7,"Ningún insumo tiene precio en "&B7))) -> Todos los 54 insumos tienen precio en CAUCA
A13: Coordenadas | F13: Clima
A14: Latitud | B14: =VLOOKUP(F7,departamento!$B$2:$E$1123,4,0) -> 6,909655 | C14: Longitud | D14: =VLOOKUP(F7,departamento!$B$2:$E$1123,3,0) -> -75,077501 | F14: Tipo | G14: Calido | H14: Rango Temperatura (°C) | I14: =VLOOKUP(G14,Tabla18[],3,0) -> T°>24 | J14: Rango Altitud (msnm) | K14: =VLOOKUP(G14,Tabla18[],2,0) -> 0-1000
A16: APTITUD (consulta upra sipra) | F16: Otras
F17: Pendiente (%) | G17: 25 | H17: Clase Agrologica | I17: I | J17: Altitud (msnm)
A19: 3. DATOS GENERALES DEL CULTIVO
A21: CULTIVO | B21: VARIEDAD | C21: TIPO CULTIVO | D21: SISTEMA PRODUCTIVO | E21: EDAD (AÑOS) | F21: CONDICION FITOSANITARIA | G21: DISTANCIA PLANTA (m) | H21: DISTANCIA SURCO (m) | I21: DENSIDAD DE SIEMBRA (plantas/ha) | J21: AREA DE CULTIVO (ha) | K21: RENDIMIENTO PRODUCTO EN FRESCO (kg/ha)
A22: Plátano | B22: Domínico hartón | C22: Permanente | D22: Convencional | E22: 6 | F22: BUENO | G22: {=IFERROR(_xlfn.LET(_xlpm.dato, _xlfn.XLOOKUP(1,(PERITO!A2:A20=A22)*(PERITO!B2:B20=B22),PERITO!C2:C20),IF(_xlpm.dato<>"",_xlpm.dato,_xlfn.XLOOKUP(1,(Caracteristicas_agronomicas!A2:A20=A22)*(Caracteristicas_agronomicas!B2:B20=B22),Caracteristicas_agronomicas!H2:H20))),_xlfn.XLOOKUP(1,(Caracteristicas_agronomicas!A2:A20=A22)*(Caracteristicas_agronomicas!B2:B20=B22),Caracteristicas_agronomicas!H2:H20))} -> 3 | H22: {=IFERROR(_xlfn.LET(_xlpm.dato, _xlfn.XLOOKUP(1,(PERITO!A2:A20=A22)*(PERITO!B2:B20=B22),PERITO!D2:D20),IF(_xlpm.dato<>"", _xlpm.dato,_xlfn.XLOOKUP(1,(Caracteristicas_agronomicas!A2:A20=A22)*(Caracteristicas_agronomicas!B2:B20=B22),Caracteristicas_agronomicas!I2:I20))),_xlfn.XLOOKUP(1,(Caracteristicas_agronomicas!A2:A20=A22)*(Caracteristicas_agronomicas!B2:B20=B22),Caracteristicas_agronomicas!I2:I20))} -> 2.5 | I22: {=IFERROR(IF(INDEX(PERITO!E:E,MATCH(1,(PERITO!A:A=A22)*(PERITO!B:B=B22),0))<>"",INDEX(PERITO!E:E,MATCH(1,(PERITO!A:A=A22)*(PERITO!B:B=B22),0)),ROUND(IF(H23="tres bolillo",10000/(G22*H22*0.866),IF(H23="cuadro",10000/(G22*H22),"")),0)),ROUND(IF(H23="tres bolillo",10000/(G22*H22*0.866),IF(H23="cuadro",10000/(G22*H22),"")),0))} -> 1540 | J22: 1
A23: Condición hídrica del predio | B23: Con disponibilidad de agua permanente | C23: Regimen de lluvias | D23: Bimodal | E23: Precipitacion anual (mm/año) | F23: 1200 | G23: MARCO DE PLANTACIÓN | H23: tres bolillo | I23: COSTO DE ARRIENDO Ha/AÑO | J23: 500000 | K23: Costo del jornal
A24: Porcentaje Fitosanitario | B24: {=IFERROR(_xlfn.SWITCH(UPPER(TRIM(F22)),"BUENO",0.95,"BUENA",0.95,"ACEPTABLE",0.7,"REGULAR",0.475,"MALO",0.2,"MALA",0.2,""),"")} -> 0.95 | C24: Valor del suelo/ ha | D24: 30000000
A26: 4. COSTOS DE PRODUCCIÓN ($/ha)
A28: Cultivo variedad | B28: =CONCATENATE(A22," ",B22) -> Plátano Domínico hartón | E28: Año | F28: Establecimiento | H28: Ciclo de vida (años) | I28: =_xlfn.XLOOKUP(B28,Caracteristicas_agronomicas!$C$2:$C$17,Caracteristicas_agronomicas!$E$2:$E$17,0) -> 5 | J28: Precio comercializacón (Kg) | K28: 4000
H29: Vida remanente | I29: =I28-E22 -> -1
A31: RUBRO | C31: SUBRUBRO | E31: ACTIVIDAD | G31: SERVICIO O INSUMO | L31: VALOR TOTAL
A32: Código | B32: Nombre | C32: Código | D32: Nombre | E32: Código | F32: Nombre | G32: Tipo | H32: Nombre | I32: Presentación | J32: Cant | K32: Precio Unitario
A33: {=_xlfn._xlws.FILTER(Base_datActividades_priorFIN!D17:O1145, (Base_datActividades_priorFIN!P17:P1145=Formulario!B28) * (Base_datActividades_priorFIN!C17:C1145=Formulario!F28), "no corresponde")} -> 1. | B33: Labores | C33: 1.3. | D33: Preparacion de Tierras | E33: 1.3.10. | F33: Trazado y Hoyado | G33: Varios | H33: Mano de Obra | I33: Jornal | J33: 26 | K33: 46666.667 | L33: 1213333.3
A34: 1. | B34: Labores | C34: 1.3. | D34: Preparacion de Tierras | E34: 1.3.12. | F34: Otras | G34: Varios | H34: Mano de Obra | I34: Jornal | J34: 3 | K34: 46666.667 | L34: 140000
A35: 1. | B35: Labores | C35: 1.4. | D35: Siembra y Sostenimiento | E35: 1.4.6. | F35: Plateo | G35: Varios | H35: Mano de Obra | I35: Jornal | J35: 17 | K35: 46666.667 | L35: 793333.33
A36: 1. | B36: Labores | C36: 1.4. | D36: Siembra y Sostenimiento | E36: 1.4.7. | F36: Resiembra | G36: Varios | H36: Mano de Obra | I36: Jornal | J36: 21 | K36: 46666.667 | L36: 980000
A37: 1. | B37: Labores | C37: 1.4. | D37: Siembra y Sostenimiento | E37: 1.4.8. | F37: Siembra Abonamiento y Tapada | G37: Varios | H37: Mano de Obra | I37: Jornal | J37: 21 | K37: 46666.667 | L37: 980000
A38: 1. | B38: Labores | C38: 1.5. | D38: Labores Culturales | E38: 1.5.6. | F38: Deshije y Destronque | G38: Varios | H38: Mano de Obra | I38: Jornal | J38: 17 | K38: 46666.667 | L38: 793333.33
A39: 1. | B39: Labores | C39: 1.6. | D39: Control Sanitario | E39: 1.6.1. | F39: Aplicación de Fungicidas | G39: Varios | H39: Mano de Obra | I39: Jornal | J39: 19 | K39: 46666.667 | L39: 886666.67
A40: 1. | B40: Labores | C40: 1.6. | D40: Control Sanitario | E40: 1.6.2. | F40: Aplicación de Insecticidas | G40: Varios | H40: Mano de Obra | I40: Jornal | J40: 19 | K40: 46666.667 | L40: 886666.67
A41: 1. | B41: Labores | C41: 1.7. | D41: Control de Malezas | E41: 1.7.1. | F41: Aplicación de Herbicidas Preemergentes | G41: Varios | H41: Mano de Obra | I41: Jornal | J41: 10 | K41: 46666.667 | L41: 466666.67
A42: 1. | B42: Labores | C42: 1.8. | D42: Fertilizacion | E42: 1.8.2. | F42: Fertilizante Simple | G42: Varios | H42: Mano de Obra | I42: Jornal | J42: 13 | K42: 46666.667 | L42: 606666.67
A43: 2. | B43: Insumos | C43: 2.1. | D43: Material Vegetal | E43: 2.1.1. | F43: Semillas o Plantulas | G43: Material_de_propagación | H43: Plátano domínico hartón colino | I43: unidad | J43: 1540 | K43: 3000 | L43: 4620000
A44: 2. | B44: Insumos | C44: 2.2. | D44: Fertilizacion | E44: 2.2.1. | F44: Simples | G44: Fertilizantes_enmiendas_y_acondicionadores_de_suelo | H44: Cloruro de Potasio 0-0-60 | I44: 50 kilogramos | J44: 11 | K44: 110000 | L44: 1210000
A45: 2. | B45: Insumos | C45: 2.2. | D45: Fertilizacion | E45: 2.2.2. | F45: compuestos | G45: Fertilizantes_enmiendas_y_acondicionadores_de_suelo | H45: Fosfato Diamónico (DAP) 18-46-0 | I45: 50 kilogramos | J45: 2 | K45: 198055.68 | L45: 396111.37
... A58: 3. | B58: Otros Costos | C58: 3.3. | D58: Arrendamiento | E58: 3.3.1. | F58: Canon | G58: Arrendamiento_de_tierras | H58: Hectárea anual. | I58: unidad | J58: 1 | K58: 500000 | L58: 500000
K65: TOTAL | L65: =SUM(L33:L64) -> 21007737
A71: Cultivo variedad | B71: =$B$28 -> Plátano Domínico hartón | E71: Año | F71: Improductivo
...

Sheet PERITO
A1: Culitvo | B1: Variedad | C1: DISTANCIA_SURCOS | D1: DISTANCIA_PLANTAS | E1: DENSIDAD_SIEMBRA
A2: Aguacate | B2: Hass
A3: Cacao | B3: Criollo
A4: Café | B4: Castillo
A5: Caña Azucar | B5: Criolla
A6: Caña Azucar | B6: POJ 2878
A7: Caña Azucar | B7: CC 93-7711 Pierna Bella
A8: Limón | B8: Tahití
A9: Limón | B9: Común
A10: Limón | B10: Mandarino
A11: Mandarina | B11: Común
A12: Mango | B12: Tommy
A13: Naranja | B13: Valencia
... A17: Plátano | B17: Domínico hartón

Sheet Entradas_Tasas
B1: CONSTRUCCIÓN DE TASA DE DESCUENTO — Resolución 620 de 2008
B2: Azul = celda editable | D2: Negro = calculado automáticamente | F2: Verde = valor de otra hoja
B4: DATOS MACROECONÓMICOS (actualizar cuando cambien las fuentes)
B5: Variable | C5: Valor E.A. | D5: Fuente | E5: Fecha consulta
B6: Tasa política monetaria BanRep | C6: 0.1125 | D6: Banco de la República | E6: 31-mar-2026
B7: DTF 90 días | C7: 0.0982 | D7: Banco de la República | E7: 30-mar al 5-abr-2026
B8: IBR (referencia) | C8: 0.105 | D8: Banco de la República | E8: Abril 2026
B9: TES 10 años (tasa libre de riesgo) | C9: 0.132 | D9: Min. Hacienda / BVC | E9: Inicio 2026
B10: IPC cierre 2025 (base legal 2026) | C10: 0.051 | D10: DANE | E10: 8-ene-2026
B11: IPC febrero 2026 (dato oficial) | C11: 0.0529 | D11: DANE | E11: Feb-2026
B12: IPC marzo 2026 (proyectado) | C12: 0.0545 | D12: BanRep / Davivienda | E12: Abr-2026
B13: Tasa de usura | C13: 0.28 | D13: Superfinanciera | E13: Abr-2026
B14: IPC a usar para deflactación (el perito elige) | C14: 0.0529 | D14: Ref: IPC cierre 2025=5.10% | IPC feb-2026=5.29% | Proyectado mar-2026=5.45%
B16: MÉTODO 1 — DTF + Prima de Riesgo Agropecuario
B17: Variable | C17: Valor | D17: Nota
B18: DTF 90 días E.A. | C18: =C7 -> 0.0982 | D18: Trae del panel Entradas actual — actualizar DTF en esa hoja
B19: Prima de riesgo agropecuario | C19: 0.1 | D19: Editable — rango sugerido: 8% a 12% según riesgo del cultivo
B20: Tasa nominal = DTF + Prima | C20: =C18+C19 -> 0.1982 | D20: Calculado automáticamente
B21: ✔ TASA REAL = (1+nom)/(1+IPC)−1 | C21: =(1+C20)/(1+C14)-1 -> 0.13799981 | D21: RESULTADO — usar en VNA si elige este método
B23: MÉTODO 2 — CAPM (Capital Asset Pricing Model)
B24: Variable | C24: Valor | D24: Nota
B25: Tasa libre de riesgo Rf (TES 10 años) | C25: 0.132 | D25: Fuente: Min. Hacienda / BVC — actualizar mensualmente
B26: Beta sectorial agrícola (β) | C26: 0.75 | D26: Editable — rango agro Colombia: 0.60–0.90
B27: Prima de mercado (Rm − Rf) | C27: 0.075 | D27: Editable — histórico Colombia: 6%–9%. Default: 7.5%
B28: Tasa CAPM nominal = Rf + β×(Rm−Rf) | C28: =C25+(C26*C27) -> 0.18825 | D28: Calculado automáticamente
B29: ✔ TASA REAL = (1+nom)/(1+IPC)−1 | C29: =(1+C28)/(1+C14)-1 -> 0.12854972 | D29: RESULTADO — usar en VNA si elige este método
B31: MÉTODO 3 — Tasa Finagro como Referencia
B32: Variable | C32: Valor | D32: Nota
B33: IBR E.A. | C33: 0.07 | D33: Promedio historico de los ultimos 10 años
B34: Tipo de productor | C34: pequeño | D34: Opciones: Pequeño / Mediano / Grande
B35: Puntos adicionales sobre IBR | C35: 0.072 | D35: Pequeño: +4.50% | Mediano: +7.20% | Grande: +7.75% (Banco Agrario mar-2026)
B36: Tasa Finagro nominal ≈ IBR + Puntos | C36: =C33+C35 -> 0.142 | D36: Aproximación E.A. — verificar en www.bancoagrario.gov.co
B37: ✔ TASA REAL = (1+nom)/(1+IPC)−1 | C37: =(1+C36)/(1+C14)-1 -> 0.084623421 | D37: RESULTADO — usar en VNA si elige este método
B39: MÉTODO 4 — WACC (Costo Promedio Ponderado de Capital)
B40: ¿El proyecto tiene deuda? | C40: si | D40: Escriba SI o NO — si es NO el WACC equivale al CAPM real del Bloque 3
B41: Variable | C41: Valor | D41: Nota
B42: % Financiado con deuda | C42: 0.7 | D42: Solo si C40=SI — ingresar entre 0 y 1 (ej: 0.40 = 40%)
B43: Tasa de la deuda E.A. (escribir libremente) | C43: 0.17 | D43: Escriba la tasa conseguida — Finagro, banco comercial u otra
B44: % Capital propio = 1 − % Deuda | C44: =1-C42 -> 0.3 | D44: Calculado automáticamente
B45: Costo capital propio (CAPM nominal) | C45: =C28 -> 0.18825 | D45: Toma el CAPM del Bloque 3
...

Sheet Entradas_calculos
A1: =Formulario!B28 -> Plátano Domínico hartón | E1: Curva de Producción (kg por ha) | J1: Entradas
A2: Etapa | B2: Edad | C2: Costo/ha | E2: Edad | F2: Producción/ha (kg) | J2: Edad inicial | K2: =Formulario!$E$22 -> 6
A3: {=IFERROR(INDEX('Rendimientos estandar_'!$C$2:$C$268,MATCH(1,(SUBSTITUTE(TRIM('Rendimientos estandar_'!$B$2:$B$268)," "," ")=SUBSTITUTE(TRIM(SUBSTITUTE(Formulario!$B$28,"_"," "))," "," "))*('Rendimientos estandar_'!$A$2:$A$268=B3),0)),"")} -> Establecimiento | B3: 1 | C3: {=IF(A3="","",_xlfn.IFS(A3="Establecimiento",Formulario!$L$65,A3="Improductivo",Formulario!$L$104,A3="Mantenimiento",Formulario!$L$146)+IF(AND(A3="Mantenimiento",A4<>"Mantenimiento"),Formulario!$L$163,0))} -> 21007737 | E3: 1 | F3: {=IFERROR(INDEX('Rendimientos estandar_'!$H$2:$H$268,MATCH(1,(SUBSTITUTE(TRIM('Rendimientos estandar_'!$B$2:$B$268)," "," ")=SUBSTITUTE(TRIM(SUBSTITUTE($A$1,"_"," "))," "," "))*('Rendimientos estandar_'!$A$2:$A$268=E3),0)),"")} -> 10450 | G3: Rendimiento ajustado = base × factor fitosanitario (Formulario!B24) | J3: Precio venta (COP/kg) | K3: =Formulario!$K$28 -> 4000
A4: {=IFERROR(INDEX('Rendimientos estandar_'!$C$2:$C$268,MATCH(1,(SUBSTITUTE(TRIM('Rendimientos estandar_'!$B$2:$B$268)," "," ")=SUBSTITUTE(TRIM(SUBSTITUTE(Formulario!$B$28,"_"," "))," "," "))*('Rendimientos estandar_'!$A$2:$A$268=B4),0)),"")} -> Mantenimiento | B4: 2 | C4: {=IF(A4="","",_xlfn.IFS(A4="Establecimiento",Formulario!$L$65,A4="Improductivo",Formulario!$L$104,A4="Mantenimiento",Formulario!$L$146)+IF(AND(A4="Mantenimiento",A5<>"Mantenimiento"),Formulario!$L$163,0))} -> 16737024 | E4: 2 | F4: {=IFERROR(INDEX('Rendimientos estandar_'!$H$2:$H$268,MATCH(1,(SUBSTITUTE(TRIM('Rendimientos estandar_'!$B$2:$B$268)," "," ")=SUBSTITUTE(TRIM(SUBSTITUTE($A$1,"_"," "))," "," "))*('Rendimientos estandar_'!$A$2:$A$268=E4),0)),"")} -> 17100 | J4: Interés (tasa) | K4: =Entradas_Tasas!$F$57 -> 0.084623421
A5: {=IFERROR(INDEX('Rendimientos estandar_'!$C$2:$C$268,MATCH(1,(SUBSTITUTE(TRIM('Rendimientos estandar_'!$B$2:$B$268)," "," ")=SUBSTITUTE(TRIM(SUBSTITUTE(Formulario!$B$28,"_"," "))," "," "))*('Rendimientos estandar_'!$A$2:$A$268=B5),0)),"")} -> Mantenimiento | B5: 3 | C5: {=IF(A5="","",_xlfn.IFS(A5="Establecimiento",Formulario!$L$65,A5="Improductivo",Formulario!$L$104,A5="Mantenimiento",Formulario!$L$146)+IF(AND(A5="Mantenimiento",A6<>"Mantenimiento"),Formulario!$L$163,0))} -> 16737024 | E5: 3 | F5: {=IFERROR(INDEX('Rendimientos estandar_'!$H$2:$H$268,MATCH(1,(SUBSTITUTE(TRIM('Rendimientos estandar_'!$B$2:$B$268)," "," ")=SUBSTITUTE(TRIM(SUBSTITUTE($A$1,"_"," "))," "," "))*('Rendimientos estandar_'!$A$2:$A$268=E5),0)),"")} -> 16245
A6: {=IFERROR(INDEX('Rendimientos estandar_'!$C$2:$C$268,MATCH(1,(SUBSTITUTE(TRIM('Rendimientos estandar_'!$B$2:$B$268)," "," ")=SUBSTITUTE(TRIM(SUBSTITUTE(Formulario!$B$28,"_"," "))," "," "))*('Rendimientos estandar_'!$A$2:$A$268=B6),0)),"")} -> Mantenimiento | B6: 4 | C6: {=IF(A6="","",_xlfn.IFS(A6="Establecimiento",Formulario!$L$65,A6="Improductivo",Formulario!$L$104,A6="Mantenimiento",Formulario!$L$146)+IF(AND(A6="Mantenimiento",A7<>"Mantenimiento"),Formulario!$L$163,0))} -> 16737024 | E6: 4 | F6: {=IFERROR(INDEX('Rendimientos estandar_'!$H$2:$H$268,MATCH(1,(SUBSTITUTE(TRIM('Rendimientos estandar_'!$B$2:$B$268)," "," ")=SUBSTITUTE(TRIM(SUBSTITUTE($A$1,"_"," "))," "," "))*('Rendimientos estandar_'!$A$2:$A$268=E6),0)),"")} -> 15390
A7: {=IFERROR(INDEX('Rendimientos estandar_'!$C$2:$C$268,MATCH(1,(SUBSTITUTE(TRIM('Rendimientos estandar_'!$B$2:$B$268)," "," ")=SUBSTITUTE(TRIM(SUBSTITUTE(Formulario!$B$28,"_"," "))," "," "))*('Rendimientos estandar_'!$A$2:$A$268=B7),0)),"")} -> Mantenimiento | B7: 5 | C7: {=IF(A7="","",_xlfn.IFS(A7="Establecimiento",Formulario!$L$65,A7="Improductivo",Formulario!$L$104,A7="Mantenimiento",Formulario!$L$146)+IF(AND(A7="Mantenimiento",A8<>"Mantenimiento"),Formulario!$L$163,0))} -> 16737024 | E7: 5 | F7: {=IFERROR(INDEX('Rendimientos estandar_'!$H$2:$H$268,MATCH(1,(SUBSTITUTE(TRIM('Rendimientos estandar_'!$B$2:$B$268)," "," ")=SUBSTITUTE(TRIM(SUBSTITUTE($A$1,"_"," "))," "," "))*('Rendimientos estandar_'!$A$2:$A$268=E7),0)),"")} -> 14535
A8: {=IFERROR(INDEX('Rendimientos estandar_'!$C$2:$C$268,MATCH(1,(SUBSTITUTE(TRIM('Rendimientos estandar_'!$B$2:$B$268)," "," ")=SUBSTITUTE(TRIM(SUBSTITUTE(Formulario!$B$28,"_"," "))," "," "))*('Rendimientos estandar_'!$A$2:$A$268=B8),0)),"")} -> Mantenimiento | B8: 6 | C8: {=IF(A8="","",_xlfn.IFS(A8="Establecimiento",Formulario!$L$65,A8="Improductivo",Formulario!$L$104,A8="Mantenimiento",Formulario!$L$146)+IF(AND(A8="Mantenimiento",A9<>"Mantenimiento"),Formulario!$L$163,0))} -> 18097824 | E8: 6 | F8: {=IFERROR(INDEX('Rendimientos estandar_'!$H$2:$H$268,MATCH(1,(SUBSTITUTE(TRIM('Rendimientos estandar_'!$B$2:$B$268)," "," ")=SUBSTITUTE(TRIM(SUBSTITUTE($A$1,"_"," "))," "," "))*('Rendimientos estandar_'!$A$2:$A$268=E8),0)),"")} -> 13680
A9: {=IFERROR(INDEX('Rendimientos estandar_'!$C$2:$C$268,MATCH(1,(SUBSTITUTE(TRIM('Rendimientos estandar_'!$B$2:$B$268)," "," ")=SUBSTITUTE(TRIM(SUBSTITUTE(Formulario!$B$28,"_"," "))," "," "))*('Rendimientos estandar_'!$A$2:$A$268=B9),0)),"")} | B9: 7 | C9: {=IF(A9="","",_xlfn.IFS(A9="Establecimiento",Formulario!$L$65,A9="Improductivo",Formulario!$L$104,A9="Mantenimiento",Formulario!$L$146)+IF(AND(A9="Mantenimiento",A10<>"Mantenimiento"),Formulario!$L$163,0))} | E9: 7 | F9: {=IFERROR(INDEX('Rendimientos estandar_'!$H$2:$H$268,MATCH(1,(SUBSTITUTE(TRIM('Rendimientos estandar_'!$B$2:$B$268)," "," ")=SUBSTITUTE(TRIM(SUBSTITUTE($A$1,"_"," "))," "," "))*('Rendimientos estandar_'!$A$2:$A$268=E9),0)),"")}
A10: {=IFERROR(INDEX('Rendimientos estandar_'!$C$2:$C$268,MATCH(1,(SUBSTITUTE(TRIM('Rendimientos estandar_'!$B$2:$B$268)," "," ")=SUBSTITUTE(TRIM(SUBSTITUTE(Formulario!$B$28,"_"," "))," "," "))*('Rendimientos estandar_'!$A$2:$A$268=B10),0)),"")} | B10: 8 | C10: {=IF(A10="","",_xlfn.IFS(A10="Establecimiento",Formulario!$L$65,A10="Improductivo",Formulario!$L$104,A10="Mantenimiento",Formulario!$L$146)+IF(AND(A10="Mantenimiento",A11<>"Mantenimiento"),Formulario!$L$163,0))} | E10: 8 | F10: {=IFERROR(INDEX('Rendimientos estandar_'!$H$2:$H$268,MATCH(1,(SUBSTITUTE(TRIM('Rendimientos estandar_'!$B$2:$B$268)," "," ")=SUBSTITUTE(TRIM(SUBSTITUTE($A$1,"_"," "))," "," "))*('Rendimientos estandar_'!$A$2:$A$268=E10),0)),"")}
A11: {=IFERROR(INDEX('Rendimientos estandar_'!$C$2:$C$268,MATCH(1,(SUBSTITUTE(TRIM('Rendimientos estandar_'!$B$2:$B$268)," "," ")=SUBSTITUTE(TRIM(SUBSTITUTE(Formulario!$B$28,"_"," "))," "," "))*('Rendimientos estandar_'!$A$2:$A$268=B11),0)),"")} | B11: 9 | C11: {=IF(A11="","",_xlfn.IFS(A11="Establecimiento",Formulario!$L$65,A11="Improductivo",Formulario!$L$104,A11="Mantenimiento",Formulario!$L$146)+IF(AND(A11="Mantenimiento",A12<>"Mantenimiento"),Formulario!$L$163,0))} | E11: 9 | F11: {=IFERROR(INDEX('Rendimientos estandar_'!$H$2:$H$268,MATCH(1,(SUBSTITUTE(TRIM('Rendimientos estandar_'!$B$2:$B$268)," "," ")=SUBSTITUTE(TRIM(SUBSTITUTE($A$1,"_"," "))," "," "))*('Rendimientos estandar_'!$A$2:$A$268=E11),0)),"")}
A12: {=IFERROR(INDEX('Rendimientos estandar_'!$C$2:$C$268,MATCH(1,(SUBSTITUTE(TRIM('Rendimientos estandar_'!$B$2:$B$268)," "," ")=SUBSTITUTE(TRIM(SUBSTITUTE(Formulario!$B$28,"_"," "))," "," "))*('Rendimientos estandar_'!$A$2:$A$268=B12),0)),"")} | B12: 10 | C12: {=IF(A12="","",_xlfn.IFS(A12="Establecimiento",Formulario!$L$65,A12="Improductivo",Formulario!$L$104,A12="Mantenimiento",Formulario!$L$146)+IF(AND(A12="Mantenimiento",A13<>"Mantenimiento"),Formulario!$L$163,0))} | E12: 10 | F12: {=IFERROR(INDEX('Rendimientos estandar_'!$H$2:$H$268,MATCH(1,(SUBSTITUTE(TRIM('Rendimientos estandar_'!$B$2:$B$268)," "," ")=SUBSTITUTE(TRIM(SUBSTITUTE($A$1,"_"," "))," "," "))*('Rendimientos estandar_'!$A$2:$A$268=E12),0)),"")}
A13: {=IFERROR(INDEX('Rendimientos estandar_'!$C$2:$C$268,MATCH(1,(SUBSTITUTE(TRIM('Rendimientos estandar_'!$B$2:$B$268)," "," ")=SUBSTITUTE(TRIM(SUBSTITUTE(Formulario!$B$28,"_"," "))," "," "))*('Rendimientos estandar_'!$A$2:$A$268=B13),0)),"")} | B13: 11 | C13: {=IF(A13="","",_xlfn.IFS(A13="Establecimiento",Formulario!$L$65,A13="Improductivo",Formulario!$L$104,A13="Mantenimiento",Formulario!$L$146)+IF(AND(A13="Mantenimiento",A14<>"Mantenimiento"),Formulario!$L$163,0))} | E13: 11 | F13: {=IFERROR(INDEX('Rendimientos estandar_'!$H$2:$H$268,MATCH(1,(SUBSTITUTE(TRIM('Rendimientos estandar_'!$B$2:$B$268)," "," ")=SUBSTITUTE(TRIM(SUBSTITUTE($A$1,"_"," "))," "," "))*('Rendimientos estandar_'!$A$2:$A$268=E13),0)),"")}
A14: {=IFERROR(INDEX('Rendimientos estandar_'!$C$2:$C$268,MATCH(1,(SUBSTITUTE(TRIM('Rendimientos estandar_'!$B$2:$B$268)," "," ")=SUBSTITUTE(TRIM(SUBSTITUTE(Formulario!$B$28,"_"," "))," "," "))*('Rendimientos estandar_'!$A$2:$A$268=B14),0)),"")} | B14: 12 | C14: {=IF(A14="","",_xlfn.IFS(A14="Establecimiento",Formulario!$L$65,A14="Improductivo",Formulario!$L$104,A14="Mantenimiento",Formulario!$L$146)+IF(AND(A14="Mantenimiento",A15<>"Mantenimiento"),Formulario!$L$163,0))} | E14: 12 | F14: {=IFERROR(INDEX('Rendimientos estandar_'!$H$2:$H$268,MATCH(1,(SUBSTITUTE(TRIM('Rendimientos estandar_'!$B$2:$B$268)," "," ")=SUBSTITUTE(TRIM(SUBSTITUTE($A$1,"_"," "))," "," "))*('Rendimientos estandar_'!$A$2:$A$268=E14),0)),"")}
A15: {=IFERROR(INDEX('Rendimientos estandar_'!$C$2:$C$268,MATCH(1,(SUBSTITUTE(TRIM('Rendimientos estandar_'!$B$2:$B$268)," "," ")=SUBSTITUTE(TRIM(SUBSTITUTE(Formulario!$B$28,"_"," "))," "," "))*('Rendimientos estandar_'!$A$2:$A$268=B15),0)),"")} | B15: 13 | C15: {=IF(A15="","",_xlfn.IFS(A15="Establecimiento",Formulario!$L$65,A15="Improductivo",Formulario!$L$104,A15="Mantenimiento",Formulario!$L$146)+IF(AND(A15="Mantenimiento",A16<>"Mantenimiento"),Formulario!$L$163,0))} | E15: 13 | F15: {=IFERROR(INDEX('Rendimientos estandar_'!$H$2:$H$268,MATCH(1,(SUBSTITUTE(TRIM('Rendimientos estandar_'!$B$2:$B$268)," "," ")=SUBSTITUTE(TRIM(SUBSTITUTE($A$1,"_"," "))," "," "))*('Rendimientos estandar_'!$A$2:$A$268=E15),0)),"")}
A16: {=IFERROR(INDEX('Rendimientos estandar_'!$C$2:$C$268,MATCH(1,(SUBSTITUTE(TRIM('Rendimientos estandar_'!$B$2:$B$268)," "," ")=SUBSTITUTE(TRIM(SUBSTITUTE(Formulario!$B$28,"_"," "))," "," "))*('Rendimientos estandar_'!$A$2:$A$268=B16),0)),"")} | B16: 14 | C16: {=IF(A16="","",_xlfn.IFS(A16="Establecimiento",Formulario!$L$65,A16="Improductivo",Formulario!$L$104,A16="Mantenimiento",Formulario!$L$146)+IF(AND(A16="Mantenimiento",A17<>"Mantenimiento"),Formulario!$L$163,0))} | E16: 14 | F16: {=IFERROR(INDEX('Rendimientos estandar_'!$H$2:$H$268,MATCH(1,(SUBSTITUTE(TRIM('Rendimientos estandar_'!$B$2:$B$268)," "," ")=SUBSTITUTE(TRIM(SUBSTITUTE($A$1,"_"," "))," "," "))*('Rendimientos estandar_'!$A$2:$A$268=E16),0)),"")}
... A31: {=IFERROR(INDEX('Rendimientos estandar_'!$C$2:$C$268,MATCH(1,(SUBSTITUTE(TRIM('Rendimientos estandar_'!$B$2:$B$268)," "," ")=SUBSTITUTE(TRIM(SUBSTITUTE(Formulario!$B$28,"_"," "))," "," "))*('Rendimientos estandar_'!$A$2:$A$268=B31),0)),"")} | B31: 29 | C31: {=IF(A31="","",_xlfn.IFS(A31="Establecimiento",Formulario!$L$65,A31="Improductivo",Formulario!$L$104,A31="Mantenimiento",Formulario!$L$146)+IF(AND(A31="Mantenimiento",A32<>"Mantenimiento"),Formulario!$L$163,0))} | E31: 29 | F31: {=IFERROR(INDEX('Rendimientos estandar_'!$H$2:$H$268,MATCH(1,(SUBSTITUTE(TRIM('Rendimientos estandar_'!$B$2:$B$268)," "," ")=SUBSTITUTE(TRIM(SUBSTITUTE($A$1,"_"," "))," "," "))*('Rendimientos estandar_'!$A$2:$A$268=E31),0)),"")}
A32: {=IFERROR(INDEX('Rendimientos estandar_'!$C$2:$C$268,MATCH(1,(SUBSTITUTE(TRIM('Rendimientos estandar_'!$B$2:$B$268)," "," ")=SUBSTITUTE(TRIM(SUBSTITUTE(Formulario!$B$28,"_"," "))," "," "))*('Rendimientos estandar_'!$A$2:$A$268=B32),0)),"")} | B32: 30 | C32: {=IF(A32="",0,_xlfn.IFS(A32="Establecimiento",Formulario!$L$65,A32="Improductivo",Formulario!$L$104,A32="Mantenimiento",Formulario!$L$146)+IF(A32="Mantenimiento",Formulario!$L$163,0))} -> 0 | E32: 30 | F32: {=IFERROR(INDEX('Rendimientos estandar_'!$H$2:$H$268,MATCH(1,(SUBSTITUTE(TRIM('Rendimientos estandar_'!$B$2:$B$268)," "," ")=SUBSTITUTE(TRIM(SUBSTITUTE($A$1,"_"," "))," "," "))*('Rendimientos estandar_'!$A$2:$A$268=E32),0)),"")}

Sheet Calculos_generales
A1: Edad | B1: Prod/ha (kg) | C1: Precio | D1: Ingreso (Prod*Precio) | E1: Costo/ha | F1: Costo Financiero | G1: Flujo Neto | H1: n (años) | I1: Interés | J1: Factor Descuento | K1: VP del Flujo | L1: VPN Remanente | M1: VPN traído al momento 0
A2: 1 | B2: =IFERROR(VLOOKUP(A2,Entradas_calculos!$E$3:$F$32,2,FALSE),0) -> 10450 | C2: =Entradas_calculos!$K$3 -> 4000 | D2: =IFERROR(B2*C2,0) -> 41800000 | E2: =IFERROR(VLOOKUP(A2,Entradas_calculos!$B$3:$C$32,2,FALSE),0) -> 21007737 | F2: =+IF(AND(A2<=Amortización!$B$3,A2-Amortización!$B$4>0),IFERROR(VLOOKUP(A2,Amortización!$A$8:$B$32,2,FALSE),0),0) -> 0 | G2: =IFERROR(D2-E2-F2,0) -> 20792263 | H2: =A2 -> 1 | I2: =Entradas_calculos!$K$4 -> 0.084623421 | J2: =(1+I2)^A2 -> 1.0846234 | K2: =IF(J2="",0,G2/J2) -> 19170030 | L2: =+NPV(Entradas_calculos!$K$4,G2:G31) -> 1.8336e+08 | P2: Total VP | Q2: =SUM(K2:K31) -> 1.8336e+08
A3: 2 | B3: =IFERROR(VLOOKUP(A3,Entradas_calculos!$E$3:$F$32,2,FALSE),0) -> 17100 | C3: =Entradas_calculos!$K$3 -> 4000 | D3: =IFERROR(B3*C3,0) -> 68400000 | E3: =IFERROR(VLOOKUP(A3,Entradas_calculos!$B$3:$C$32,2,FALSE),0) -> 16737024 | F3: =+IF(AND(A3<=Amortización!$B$3,A3-Amortización!$B$4>0),IFERROR(VLOOKUP(A3,Amortización!$A$8:$B$32,2,FALSE),0),0) -> 0 | G3: =IFERROR(D3-E3-F3,0) -> 51662976 | H3: =A3 -> 2 | I3: =Entradas_calculos!$K$4 -> 0.084623421 | J3: =(1+I3)^A3 -> 1.176408 | K3: =IF(J3="",0,G3/J3) -> 43915868 | L3: =+NPV(Entradas_calculos!$K$4,G3:G31) -> 1.7808428e+08 | P3: TIR | Q3: =IRR(G2:G31,0.1) -> #NUM!
A4: 3 | B4: =IFERROR(VLOOKUP(A4,Entradas_calculos!$E$3:$F$32,2,FALSE),0) -> 16245 | C4: =Entradas_calculos!$K$3 -> 4000 | D4: =IFERROR(B4*C4,0) -> 64980000 | E4: =IFERROR(VLOOKUP(A4,Entradas_calculos!$B$3:$C$32,2,FALSE),0) -> 16737024 | F4: =+IF(AND(A4<=Amortización!$B$3,A4-Amortización!$B$4>0),IFERROR(VLOOKUP(A4,Amortización!$A$8:$B$32,2,FALSE),0),0) -> 0 | G4: =IFERROR(D4-E4-F4,0) -> 48242976 | H4: =A4 -> 3 | I4: =Entradas_calculos!$K$4 -> 0.084623421 | J4: =(1+I4)^A4 -> 1.2759596 | K4: =IF(J4="",0,G4/J4) -> 37809171 | L4: =+NPV(Entradas_calculos!$K$4,G4:G31) -> 1.4149141e+08 | M4: =IF(H4="","",L4/((1+Entradas_calculos!$K$4)^H4)) -> 1.1089019e+08 | P4: Relacion C/B | Q4: {=IFERROR(NPV(Entradas_calculos!$K$4,D2:D30)/NPV(Entradas_calculos!$K$4,E2:E30+F2:F30),"-")} -> -
A5: 4 | B5: =IFERROR(VLOOKUP(A5,Entradas_calculos!$E$3:$F$32,2,FALSE),0) -> 15390 | C5: =Entradas_calculos!$K$3 -> 4000 | D5: =IFERROR(B5*C5,0) -> 61560000 | E5: =IFERROR(VLOOKUP(A5,Entradas_calculos!$B$3:$C$32,2,FALSE),0) -> 16737024 | F5: =+IF(AND(A5<=Amortización!$B$3,A5-Amortización!$B$4>0),IFERROR(VLOOKUP(A5,Amortización!$A$8:$B$32,2,FALSE),0),0) -> 0 | G5: =IFERROR(D5-E5-F5,0) -> 44822976 | H5: =A5 -> 4 | I5: =Entradas_calculos!$K$4 -> 0.084623421 | J5: =(1+I5)^A5 -> 1.3839357 | K5: =IF(J5="",0,G5/J5) -> 32388048 | L5: =+NPV(Entradas_calculos!$K$4,G5:G31) -> 1.0522192e+08 | M5: =IF(H5="","",L5/((1+Entradas_calculos!$K$4)^H5)) -> 76030930 | P5: punto equilibrio | Q5: {=IFERROR(_xlfn.LET(_xlpm.idx,MATCH(TRUE,MMULT(--(ROW(G2:G30)>=TRANSPOSE(ROW(G2:G30))),G2:G30)>=0,0),_xlpm.prev,SUM(OFFSET(G2,0,0,_xlpm.idx-1,1)),_xlpm.flujoAct,INDEX(G2:G30,_xlpm.idx),(_xlpm.idx-1)+(-_xlpm.prev/_xlpm.flujoAct)),"No alcanza")} -> No alcanza
A6: 5 | B6: =IFERROR(VLOOKUP(A6,Entradas_calculos!$E$3:$F$32,2,FALSE),0) -> 14535 | C6: =Entradas_calculos!$K$3 -> 4000 | D6: =IFERROR(B6*C6,0) -> 58140000 | E6: =IFERROR(VLOOKUP(A6,Entradas_calculos!$B$3:$C$32,2,FALSE),0) -> 16737024 | F6: =+IF(AND(A6<=Amortización!$B$3,A6-Amortización!$B$4>0),IFERROR(VLOOKUP(A6,Amortización!$A$8:$B$32,2,FALSE),0),0) -> 0 | G6: =IFERROR(D6-E6-F6,0) -> 41402976 | H6: =A6 -> 5 | I6: =Entradas_calculos!$K$4 -> 0.084623421 | J6: =(1+I6)^A6 -> 1.5010491 | K6: =IF(J6="",0,G6/J6) -> 27582693 | L6: =+NPV(Entradas_calculos!$K$4,G6:G31) -> 69303181 | M6: =IF(H6="","",L6/((1+Entradas_calculos!$K$4)^H6)) -> 46169830
A7: 6 | B7: =IFERROR(VLOOKUP(A7,Entradas_calculos!$E$3:$F$32,2,FALSE),0) -> 13680 | C7: =Entradas_calculos!$K$3 -> 4000 | D7: =IFERROR(B7*C7,0) -> 54720000 | E7: =IFERROR(VLOOKUP(A7,Entradas_calculos!$B$3:$C$32,2,FALSE),0) -> 18097824 | F7: =+IF(AND(A7<=Amortización!$B$3,A7-Amortización!$B$4>0),IFERROR(VLOOKUP(A7,Amortización!$A$8:$B$32,2,FALSE),0),0) -> 0 | G7: =IFERROR(D7-E7-F7,0) -> 36622176 | H7: =A7 -> 6 | I7: =Entradas_calculos!$K$4 -> 0.084623421 | J7: =(1+I7)^A7 -> 1.628073 | K7: =IF(J7="",0,G7/J7) -> 22494186 | L7: =+NPV(Entradas_calculos!$K$4,G7:G31) -> 33764877 | M7: =IF(H7="","",L7/((1+Entradas_calculos!$K$4)^H7)) -> 20739167
A8: 7 | B8: =IFERROR(VLOOKUP(A8,Entradas_calculos!$E$3:$F$32,2,FALSE),0) | C8: =Entradas_calculos!$K$3 -> 4000 | D8: =IFERROR(B8*C8,0) -> 0 | E8: =IFERROR(VLOOKUP(A8,Entradas_calculos!$B$3:$C$32,2,FALSE),0) | F8: =+IF(AND(A8<=Amortización!$B$3,A8-Amortización!$B$4>0),IFERROR(VLOOKUP(A8,Amortización!$A$8:$B$32,2,FALSE),0),0) -> 0 | G8: =IFERROR(D8-E8-F8,0) -> 0 | H8: =A8 -> 7 | I8: =Entradas_calculos!$K$4 -> 0.084623421 | J8: =(1+I8)^A8 -> 1.7658461 | K8: =IF(J8="",0,G8/J8) -> 0 | L8: =+NPV(Entradas_calculos!$K$4,G8:G31) -> 0 | M8: =IF(H8="","",L8/((1+Entradas_calculos!$K$4)^H8)) -> 0
A9: 8 | B9: =IFERROR(VLOOKUP(A9,Entradas_calculos!$E$3:$F$32,2,FALSE),0) | C9: =Entradas_calculos!$K$3 -> 4000 | D9: =IFERROR(B9*C9,0) -> 0 | E9: =IFERROR(VLOOKUP(A9,Entradas_calculos!$B$3:$C$32,2,FALSE),0) | F9: =+IF(AND(A9<=Amortización!$B$3,A9-Amortización!$B$4>0),IFERROR(VLOOKUP(A9,Amortización!$A$8:$B$32,2,FALSE),0),0) -> 0 | G9: =IFERROR(D9-E9-F9,0) -> 0 | H9: =A9 -> 8 | I9: =Entradas_calculos!$K$4 -> 0.084623421 | J9: =(1+I9)^A9 -> 1.915278 | K9: =IF(J9="",0,G9/J9) -> 0 | L9: =+NPV(Entradas_calculos!$K$4,Calculos_generales!G9:G31) -> 0 | M9: =IF(H9="","",L9/((1+Entradas_calculos!$K$4)^H9)) -> 0
A10: 9 | B10: =IFERROR(VLOOKUP(A10,Entradas_calculos!$E$3:$F$32,2,FALSE),0) | C10: =Entradas_calculos!$K$3 -> 4000 | D10: =IFERROR(B10*C10,0) -> 0 | E10: =IFERROR(VLOOKUP(A10,Entradas_calculos!$B$3:$C$32,2,FALSE),0) | F10: =+IF(AND(A10<=Amortización!$B$3,A10-Amortización!$B$4>0),IFERROR(VLOOKUP(A10,Amortización!$A$8:$B$32,2,FALSE),0),0) -> 0 | G10: =IFERROR(D10-E10-F10,0) -> 0 | H10: =A10 -> 9 | I10: =Entradas_calculos!$K$4 -> 0.084623421 | J10: =(1+I10)^A10 -> 2.0773554 | K10: =IF(J10="",0,G10/J10) -> 0 | L10: =+NPV(Entradas_calculos!$K$4,Calculos_generales!G10:G32) -> 0 | M10: =IF(H10="","",L10/((1+Entradas_calculos!$K$4)^H10)) -> 0
A11: 10 | B11: =IFERROR(VLOOKUP(A11,Entradas_calculos!$E$3:$F$32,2,FALSE),0) | C11: =Entradas_calculos!$K$3 -> 4000 | D11: =IFERROR(B11*C11,0) -> 0 | E11: =IFERROR(VLOOKUP(A11,Entradas_calculos!$B$3:$C$32,2,FALSE),0) | F11: =+IF(AND(A11<=Amortización!$B$3,A11-Amortización!$B$4>0),IFERROR(VLOOKUP(A11,Amortización!$A$8:$B$32,2,FALSE),0),0) -> 0 | G11: =IFERROR(D11-E11-F11,0) -> 0 | H11: =A11 -> 10 | I11: =Entradas_calculos!$K$4 -> 0.084623421 | J11: =(1+I11)^A11 -> 2.2531483 | K11: =IF(J11="",0,G11/J11) -> 0 | L11: =+NPV(Entradas_calculos!$K$4,G11:G31) -> 0 | M11: =+L11/((1+Entradas_calculos!$K$4)^Calculos_generales!H11) -> 0
A12: 11 | B12: =IFERROR(VLOOKUP(A12,Entradas_calculos!$E$3:$F$32,2,FALSE),0) | C12: =Entradas_calculos!$K$3 -> 4000 | D12: =IFERROR(B12*C12,0) -> 0 | E12: =IFERROR(VLOOKUP(A12,Entradas_calculos!$B$3:$C$32,2,FALSE),0) | F12: =+IF(AND(A12<=Amortización!$B$3,A12-Amortización!$B$4>0),IFERROR(VLOOKUP(A12,Amortización!$A$8:$B$32,2,FALSE),0),0) -> 0 | G12: =IFERROR(D12-E12-F12,0) -> 0 | H12: =A12 -> 11 | I12: =Entradas_calculos!$K$4 -> 0.084623421 | J12: =(1+I12)^A12 -> 2.4438174 | K12: =IF(J12="",0,G12/J12) -> 0 | L12: =+NPV(Entradas_calculos!$K$4,Calculos_generales!G12:G34) -> 0 | M12: =+L12/((1+Entradas_calculos!$K$4)^Calculos_generales!H12) -> 0
A13: 12 | B13: =IFERROR(VLOOKUP(A13,Entradas_calculos!$E$3:$F$32,2,FALSE),0) | C13: =Entradas_calculos!$K$3 -> 4000 | D13: =IFERROR(B13*C13,0) -> 0 | E13: =IFERROR(VLOOKUP(A13,Entradas_calculos!$B$3:$C$32,2,FALSE),0) | F13: =+IF(AND(A13<=Amortización!$B$3,A13-Amortización!$B$4>0),IFERROR(VLOOKUP(A13,Amortización!$A$8:$B$32,2,FALSE),0),0) -> 0 | G13: =IFERROR(D13-E13-F13,0) -> 0 | H13: =A13 -> 12 | I13: =Entradas_calculos!$K$4 -> 0.084623421 | J13: =(1+I13)^A13 -> 2.6506216 | K13: =IF(J13="",0,G13/J13) -> 0 | L13: =+NPV(Entradas_calculos!$K$4,Calculos_generales!G13:G35) -> 0 | M13: =+L13/((1+Entradas_calculos!$K$4)^Calculos_generales!H13) -> 0
A14: 13 | B14: =IFERROR(VLOOKUP(A14,Entradas_calculos!$E$3:$F$32,2,FALSE),0) | C14: =Entradas_calculos!$K$3 -> 4000 | D14: =IFERROR(B14*C14,0) -> 0 | E14: =IFERROR(VLOOKUP(A14,Entradas_calculos!$B$3:$C$32,2,FALSE),0) | F14: =+IF(AND(A14<=Amortización!$B$3,A14-Amortización!$B$4>0),IFERROR(VLOOKUP(A14,Amortización!$A$8:$B$32,2,FALSE),0),0) -> 0 | G14: =IFERROR(D14-E14-F14,0) -> 0 | H14: =A14 -> 13 | I14: =Entradas_calculos!$K$4 -> 0.084623421 | J14: =(1+I14)^A14 -> 2.8749263 | K14: =IF(J14="",0,G14/J14) -> 0 | L14: =+NPV(Entradas_calculos!$K$4,Calculos_generales!G14:G36) -> 0 | M14: =+L14/((1+Entradas_calculos!$K$4)^Calculos_generales!H14) -> 0
A15: 14 | B15: =IFERROR(VLOOKUP(A15,Entradas_calculos!$E$3:$F$32,2,FALSE),0) | C15: =Entradas_calculos!$K$3 -> 4000 | D15: =IFERROR(B15*C15,0) -> 0 | E15: =IFERROR(VLOOKUP(A15,Entradas_calculos!$B$3:$C$32,2,FALSE),0) | F15: =+IF(AND(A15<=Amortización!$B$3,A15-Amortización!$B$4>0),IFERROR(VLOOKUP(A15,Amortización!$A$8:$B$32,2,FALSE),0),0) -> 0 | G15: =IFERROR(D15-E15-F15,0) -> 0 | H15: =A15 -> 14 | I15: =Entradas_calculos!$K$4 -> 0.084623421 | J15: =(1+I15)^A15 -> 3.1182124 | K15: =IF(J15="",0,G15/J15) -> 0 | L15: =+NPV(Entradas_calculos!$K$4,Calculos_generales!G15:G37) -> 0 | M15: =+L15/((1+Entradas_calculos!$K$4)^Calculos_generales!H15) -> 0
A16: 15 | B16: =IFERROR(VLOOKUP(A16,Entradas_calculos!$E$3:$F$32,2,FALSE),0) | C16: =Entradas_calculos!$K$3 -> 4000 | D16: =IFERROR(B16*C16,0) -> 0 | E16: =IFERROR(VLOOKUP(A16,Entradas_calculos!$B$3:$C$32,2,FALSE),0) | F16: =+IF(AND(A16<=Amortización!$B$3,A16-Amortización!$B$4>0),IFERROR(VLOOKUP(A16,Amortización!$A$8:$B$32,2,FALSE),0),0) -> 0 | G16: =IFERROR(D16-E16-F16,0) -> 0 | H16: =A16 -> 15 | I16: =Entradas_calculos!$K$4 -> 0.084623421 | J16: =(1+I16)^A16 -> 3.3820862 | K16: =IF(J16="",0,G16/J16) -> 0 | L16: =+NPV(Entradas_calculos!$K$4,Calculos_generales!G16:G38) -> 0 | M16: =+L16/((1+Entradas_calculos!$K$4)^Calculos_generales!H16) -> 0
A17: 16 | B17: =IFERROR(VLOOKUP(A17,Entradas_calculos!$E$3:$F$32,2,FALSE),0) | C17: =Entradas_calculos!$K$3 -> 4000 | D17: =IFERROR(B17*C17,0) -> 0 | E17: =IFERROR(VLOOKUP(A17,Entradas_calculos!$B$3:$C$32,2,FALSE),0) | F17: =+IF(AND(A17<=Amortización!$B$3,A17-Amortización!$B$4>0),IFERROR(VLOOKUP(A17,Amortización!$A$8:$B$32,2,FALSE),0),0) -> 0 | G17: =IFERROR(D17-E17-F17,0) -> 0 | H17: =A17 -> 16 | I17: =Entradas_calculos!$K$4 -> 0.084623421 | J17: =(1+I17)^A17 -> 3.6682899 | K17: =IF(J17="",0,G17/J17) -> 0 | L17: =+NPV(Entradas_calculos!$K$4,Calculos_generales!G17:G39) -> 0 | M17: =+L17/((1+Entradas_calculos!$K$4)^Calculos_generales!H17) -> 0
A18: 17 | B18: =IFERROR(VLOOKUP(A18,Entradas_calculos!$E$3:$F$32,2,FALSE),0) | C18: =Entradas_calculos!$K$3 -> 4000 | D18: =IFERROR(B18*C18,0) -> 0 | E18: =IFERROR(VLOOKUP(A18,Entradas_calculos!$B$3:$C$32,2,FALSE),0) | F18: =+IF(AND(A18<=Amortización!$B$3,A18-Amortización!$B$4>0),IFERROR(VLOOKUP(A18,Amortización!$A$8:$B$32,2,FALSE),0),0) -> 0 | G18: =IFERROR(D18-E18-F18,0) -> 0 | H18: =A18 -> 17 | I18: =Entradas_calculos!$K$4 -> 0.084623421 | J18: =(1+I18)^A18 -> 3.9787132 | K18: =IF(J18="",0,G18/J18) -> 0 | L18: =+NPV(Entradas_calculos!$K$4,Calculos_generales!G18:G40) -> 0 | M18: =+L18/((1+Entradas_calculos!$K$4)^Calculos_generales!H18) -> 0
A19: 18 | B19: =IFERROR(VLOOKUP(A19,Entradas_calculos!$E$3:$F$32,2,FALSE),0) | C19: =Entradas_calculos!$K$3 -> 4000 | D19: =IFERROR(B19*C19,0) -> 0 | E19: =IFERROR(VLOOKUP(A19,Entradas_calculos!$B$3:$C$32,2,FALSE),0) | F19: =+IF(AND(A19<=Amortización!$B$3,A19-Amortización!$B$4>0),IFERROR(VLOOKUP(A19,Amortización!$A$8:$B$32,2,FALSE),0),0) -> 0 | G19: =IFERROR(D19-E19-F19,0) -> 0 | H19: =A19 -> 18 | I19: =Entradas_calculos!$K$4 -> 0.084623421 | J19: =(1+I19)^A19 -> 4.3154055 | K19: =IF(J19="",0,G19/J19) -> 0 | L19: =+NPV(Entradas_calculos!$K$4,Calculos_generales!G19:G41) -> 0 | M19: =+L19/((1+Entradas_calculos!$K$4)^Calculos_generales!H19) -> 0
A20: 19 | B20: =IFERROR(VLOOKUP(A20,Entradas_calculos!$E$3:$F$32,2,FALSE),0) | C20: =Entradas_calculos!$K$3 -> 4000 | D20: =IFERROR(B20*C20,0) -> 0 | E20: =IFERROR(VLOOKUP(A20,Entradas_calculos!$B$3:$C$32,2,FALSE),0) | F20: =+IF(AND(A20<=Amortización!$B$3,A20-Amortización!$B$4>0),IFERROR(VLOOKUP(A20,Amortización!$A$8:$B$32,2,FALSE),0),0) -> 0 | G20: =IFERROR(D20-E20-F20,0) -> 0 | H20: =A20 -> 19 | I20: =Entradas_calculos!$K$4 -> 0.084623421 | J20: =(1+I20)^A20 -> 4.6805898 | K20: =IF(J20="",0,G20/J20) -> 0 | L20: =+NPV(Entradas_calculos!$K$4,Calculos_generales!G20:G42) -> 0 | M20: =+L20/((1+Entradas_calculos!$K$4)^Calculos_generales!H20) -> 0
A21: 20 | B21: =IFERROR(VLOOKUP(A21,Entradas_calculos!$E$3:$F$32,2,FALSE),0) | C21: =Entradas_calculos!$K$3 -> 4000 | D21: =IFERROR(B21*C21,0) -> 0 | E21: =IFERROR(VLOOKUP(A21,Entradas_calculos!$B$3:$C$32,2,FALSE),0) | F21: =+IF(AND(A21<=Amortización!$B$3,A21-Amortización!$B$4>0),IFERROR(VLOOKUP(A21,Amortización!$A$8:$B$32,2,FALSE),0),0) -> 0 | G21: =IFERROR(D21-E21-F21,0) -> 0 | H21: =A21 -> 20 | I21: =Entradas_calculos!$K$4 -> 0.084623421 | J21: =(1+I21)^A21 -> 5.0766774 | K21: =IF(J21="",0,G21/J21) -> 0 | L21: =+NPV(Entradas_calculos!$K$4,Calculos_generales!G21:G43) -> 0 | M21: =+L21/((1+Entradas_calculos!$K$4)^Calculos_generales!H21) -> 0
A22: 21 | B22: =IFERROR(VLOOKUP(A22,Entradas_calculos!$E$3:$F$32,2,FALSE),0) | C22: =Entradas_calculos!$K$3 -> 4000 | D22: =IFERROR(B22*C22,0) -> 0 | E22: =IFERROR(VLOOKUP(A22,Entradas_calculos!$B$3:$C$32,2,FALSE),0) | F22: =+IF(AND(A22<=Amortización!$B$3,A22-Amortización!$B$4>0),IFERROR(VLOOKUP(A22,Amortización!$A$8:$B$32,2,FALSE),0),0) -> 0 | G22: =IFERROR(D22-E22-F22,0) -> 0 | H22: =A22 -> 21 | I22: =Entradas_calculos!$K$4 -> 0.084623421 | J22: =(1+I22)^A22 -> 5.5062832 | K22: =IF(J22="",0,G22/J22) -> 0 | L22: =+NPV(Entradas_calculos!$K$4,Calculos_generales!G22:G44) -> 0 | M22: =+L22/((1+Entradas_calculos!$K$4)^Calculos_generales!H22) -> 0
A23: 22 | B23: =IFERROR(VLOOKUP(A23,Entradas_calculos!$E$3:$F$32,2,FALSE),0) | C23: =Entradas_calculos!$K$3 -> 4000 | D23: =IFERROR(B23*C23,0) -> 0 | E23: =IFERROR(VLOOKUP(A23,Entradas_calculos!$B$3:$C$32,2,FALSE),0) | F23: =+IF(AND(A23<=Amortización!$B$3,A23-Amortización!$B$4>0),IFERROR(VLOOKUP(A23,Amortización!$A$8:$B$32,2,FALSE),0),0) -> 0 | G23: =IFERROR(D23-E23-F23,0) -> 0 | H23: =A23 -> 22 | I23: =Entradas_calculos!$K$4 -> 0.084623421 | J23: =(1+I23)^A23 -> 5.9722437 | K23: =IF(J23="",0,G23/J23) -> 0 | L23: =+NPV(Entradas_calculos!$K$4,Calculos_generales!G23:G45) -> 0 | M23: =+L23/((1+Entradas_calculos!$K$4)^Calculos_generales!H23) -> 0
... A26: 25 | B26: =IFERROR(VLOOKUP(A26,Entradas_calculos!$E$3:$F$32,2,FALSE),0) | C26: =Entradas_calculos!$K$3 -> 4000 | D26: =IFERROR(B26*C26,0) -> 0 | E26: =IFERROR(VLOOKUP(A26,Entradas_calculos!$B$3:$C$32,2,FALSE),0) | F26: =+IF(AND(A26<=Amortización!$B$3,A26-Amortización!$B$4>0),IFERROR(VLOOKUP(A26,Amortización!$A$8:$B$32,2,FALSE),0),0) -> 0 | G26: =IFERROR(D26-E26-F26,0) -> 0 | H26: =A26 -> 25 | I26: =Entradas_calculos!$K$4 -> 0.084623421 | J26: =(1+I26)^A26 -> 7.6203419 | K26: =IF(J26="",0,G26/J26) -> 0 | L26: =+NPV(Entradas_calculos!$K$4,Calculos_generales!G26:G48) -> 0 | M26: =+L26/((1+Entradas_calculos!$K$4)^Calculos_generales!H26) -> 0
A27: 26 | B27: =IFERROR(VLOOKUP(A27,Entradas_calculos!$E$3:$F$32,2,FALSE),0) | C27: =Entradas_calculos!$K$3 -> 4000 | D27: =IFERROR(B27*C27,0) -> 0 | E27: =IFERROR(VLOOKUP(A27,Entradas_calculos!$B$3:$C$32,2,FALSE),0) | F27: =+IF(AND(A27<=Amortización!$B$3,A27-Amortización!$B$4>0),IFERROR(VLOOKUP(A27,Amortización!$A$8:$B$32,2,FALSE),0),0) -> 0 | G27: =IFERROR(D27-E27-F27,0) -> 0 | H27: =A27 -> 26 | I27: =Entradas_calculos!$K$4 -> 0.084623421 | J27: =(1+I27)^A27 -> 8.2652013 | K27: =IF(J27="",0,G27/J27) -> 0 | L27: =+NPV(Entradas_calculos!$K$4,Calculos_generales!G27:G49) -> 0
A28: 27 | B28: =IFERROR(VLOOKUP(A28,Entradas_calculos!$E$3:$F$32,2,FALSE),0) | C28: =Entradas_calculos!$K$3 -> 4000 | D28: =IFERROR(B28*C28,0) -> 0 | E28: =IFERROR(VLOOKUP(A28,Entradas_calculos!$B$3:$C$32,2,FALSE),0) | F28: =+IF(AND(A28<=Amortización!$B$3,A28-Amortización!$B$4>0),IFERROR(VLOOKUP(A28,Amortización!$A$8:$B$32,2,FALSE),0),0) -> 0 | G28: =IFERROR(D28-E28-F28,0) -> 0 | H28: =A28 -> 27 | I28: =Entradas_calculos!$K$4 -> 0.084623421 | J28: =(1+I28)^A28 -> 8.9646309 | K28: =IF(J28="",0,G28/J28) -> 0 | L28: =+NPV(Entradas_calculos!$K$4,Calculos_generales!G28:G50) -> 0
A29: 28 | B29: =IFERROR(VLOOKUP(A29,Entradas_calculos!$E$3:$F$32,2,FALSE),0) | C29: =Entradas_calculos!$K$3 -> 4000 | D29: =IFERROR(B29*C29,0) -> 0 | E29: =IFERROR(VLOOKUP(A29,Entradas_calculos!$B$3:$C$32,2,FALSE),0) | F29: =+IF(AND(A29<=Amortización!$B$3,A29-Amortización!$B$4>0),IFERROR(VLOOKUP(A29,Amortización!$A$8:$B$32,2,FALSE),0),0) -> 0 | G29: =IFERROR(D29-E29-F29,0) -> 0 | H29: =A29 -> 28 | I29: =Entradas_calculos!$K$4 -> 0.084623421 | J29: =(1+I29)^A29 -> 9.7232486 | K29: =IF(J29="",0,G29/J29) -> 0 | L29: =+NPV(Entradas_calculos!$K$4,Calculos_generales!G29:G51) -> 0
A30: 29 | B30: =IFERROR(VLOOKUP(A30,Entradas_calculos!$E$3:$F$32,2,FALSE),0) | C30: =Entradas_calculos!$K$3 -> 4000 | D30: =IFERROR(B30*C30,0) -> 0 | E30: =IFERROR(VLOOKUP(A30,Entradas_calculos!$B$3:$C$32,2,FALSE),0) | F30: =+IF(AND(A30<=Amortización!$B$3,A30-Amortización!$B$4>0),IFERROR(VLOOKUP(A30,Amortización!$A$8:$B$32,2,FALSE),0),0) -> 0 | G30: =IFERROR(D30-E30-F30,0) -> 0 | H30: =A30 -> 29 | I30: =Entradas_calculos!$K$4 -> 0.084623421 | J30: =(1+I30)^A30 -> 10.546063 | K30: =IF(J30="",0,G30/J30) -> 0 | L30: =+NPV(Entradas_calculos!$K$4,Calculos_generales!G30:G52) -> 0
A31: 30 | B31: =IFERROR(VLOOKUP(A31,Entradas_calculos!$E$3:$F$32,2,FALSE),0) | C31: =Entradas_calculos!$K$3 -> 4000 | D31: =IFERROR(B31*C31,0) -> 0 | E31: =IFERROR(VLOOKUP(A31,Entradas_calculos!$B$3:$C$32,2,FALSE),0) -> 0 | F31: =+IF(AND(A31<=Amortización!$B$3,A31-Amortización!$B$4>0),IFERROR(VLOOKUP(A31,Amortización!$A$8:$B$32,2,FALSE),0),0) -> 0 | G31: =IFERROR(D31-E31-F31,0) -> 0 | H31: =A31 -> 30 | I31: =Entradas_calculos!$K$4 -> 0.084623421 | J31: =(1+I31)^A31 -> 11.438507 | K31: =IF(J31="",0,G31/J31) -> 0 | L31: =+NPV(Entradas_calculos!$K$4,Calculos_generales!G31:G53) -> 0

Sheet Amortización
A1: Inversión Inicial | B1: =Entradas_calculos!N4 -> 0
A2: Tasa EA (i + IBR) | B2: =Entradas_calculos!N5 -> 0
A3: Periodo (años) | B3: =Entradas_calculos!N6 -> 0
A4: Periodo gracia | B4: =Entradas_calculos!N7 -> 0
A5: ¿Hay préstamo? | B5: =Entradas_calculos!N2 -> 0
A6: Período | B6: Cuota | C6: Amortización | D6: Interés | E6: Saldo deuda
A7: 0 | B7: =IF($B$5="Sí",IFERROR(PMT($B$2,$B$3-$B$4,-($B$1*(1+$B$2)^$B$4)),0),0) -> 0 | E7: =IF($B$5="Sí",$B$1*(1+$B$2)^$B$4,0) -> 0
A8: 1 | B8: =IF($B$5="Sí",IF(A8>$B$3,0,B7),0) -> 0 | C8: =IF($B$5="Sí",IF(A8<=$B$4,0,B8-D8),0) -> 0 | D8: =IF($B$5="Sí",E7*$B$2,0) -> 0 | E8: =IF($B$5="Sí",MAX(E7-C8,0),0) -> 0
A9: 2 | B9: =IF($B$5="Sí",IF(A9>$B$3,0,B8),0) -> 0 | C9: =IF($B$5="Sí",IF(A9<=$B$4,0,B9-D9),0) -> 0 | D9: =IF($B$5="Sí",E8*$B$2,0) -> 0 | E9: =IF($B$5="Sí",MAX(E8-C9,0),0) -> 0
A10: 3 | B10: =IF($B$5="Sí",IF(A10>$B$3,0,B9),0) -> 0 | C10: =IF($B$5="Sí",IF(A10<=$B$4,0,B10-D10),0) -> 0 | D10: =IF($B$5="Sí",E9*$B$2,0) -> 0 | E10: =IF($B$5="Sí",MAX(E9-C10,0),0) -> 0
A11: 4 | B11: =IF($B$5="Sí",IF(A11>$B$3,0,B10),0) -> 0 | C11: =IF($B$5="Sí",IF(A11<=$B$4,0,B11-D11),0) -> 0 | D11: =IF($B$5="Sí",E10*$B$2,0) -> 0 | E11: =IF($B$5="Sí",MAX(E10-C11,0),0) -> 0
A12: 5 | B12: =IF($B$5="Sí",IF(A12>$B$3,0,B11),0) -> 0 | C12: =IF($B$5="Sí",IF(A12<=$B$4,0,B12-D12),0) -> 0 | D12: =IF($B$5="Sí",E11*$B$2,0) -> 0 | E12: =IF($B$5="Sí",MAX(E11-C12,0),0) -> 0
A13: 6 | B13: =IF($B$5="Sí",IF(A13>$B$3,0,B12),0) -> 0 | C13: =IF($B$5="Sí",IF(A13<=$B$4,0,B13-D13),0) -> 0 | D13: =IF($B$5="Sí",E12*$B$2,0) -> 0 | E13: =IF($B$5="Sí",MAX(E12-C13,0),0) -> 0
A14: 7 | B14: =IF($B$5="Sí",IF(A14>$B$3,0,B13),0) -> 0 | C14: =IF($B$5="Sí",IF(A14<=$B$4,0,B14-D14),0) -> 0 | D14: =IF($B$5="Sí",E13*$B$2,0) -> 0 | E14: =IF($B$5="Sí",MAX(E13-C14,0),0) -> 0
A15: 8 | B15: =IF($B$5="Sí",IF(A15>$B$3,0,B14),0) -> 0 | C15: =IF($B$5="Sí",IF(A15<=$B$4,0,B15-D15),0) -> 0 | D15: =IF($B$5="Sí",E14*$B$2,0) -> 0 | E15: =IF($B$5="Sí",MAX(E14-C15,0),0) -> 0
A16: 9 | B16: =IF($B$5="Sí",IF(A16>$B$3,0,B15),0) -> 0 | C16: =IF($B$5="Sí",IF(A16<=$B$4,0,B16-D16),0) -> 0 | D16: =IF($B$5="Sí",E15*$B$2,0) -> 0 | E16: =IF($B$5="Sí",MAX(E15-C16,0),0) -> 0
A17: 10 | B17: =IF($B$5="Sí",IF(A17>$B$3,0,B16),0) -> 0 | C17: =IF($B$5="Sí",IF(A17<=$B$4,0,B17-D17),0) -> 0 | D17: =IF($B$5="Sí",E16*$B$2,0) -> 0 | E17: =IF($B$5="Sí",MAX(E16-C17,0),0) -> 0
A18: 11 | B18: =IF($B$5="Sí",IF(A18>$B$3,0,B17),0) -> 0 | C18: =IF($B$5="Sí",IF(A18<=$B$4,0,B18-D18),0) -> 0 | D18: =IF($B$5="Sí",E17*$B$2,0) -> 0 | E18: =IF($B$5="Sí",MAX(E17-C18,0),0) -> 0
A19: 12 | B19: =IF($B$5="Sí",IF(A19>$B$3,0,B18),0) -> 0 | C19: =IF($B$5="Sí",IF(A19<=$B$4,0,B19-D19),0) -> 0 | D19: =IF($B$5="Sí",E18*$B$2,0) -> 0 | E19: =IF($B$5="Sí",MAX(E18-C19,0),0) -> 0
... A32: 25 | B32: =IF($B$5="Sí",IF(A32>$B$3,0,B31),0) -> 0 | C32: =IF($B$5="Sí",IF(A32<=$B$4,0,B32-D32),0) -> 0 | D32: =IF($B$5="Sí",E31*$B$2,0) -> 0 | E32: =IF($B$5="Sí",MAX(E31-C32,0),0) -> 0

Sheet calculo_etapa_vegetativa
A1: Costos de siembra por hectárea etapa improductiva
A2: Año | B2: Costo en pesos constantes/ha | C2: Costo Financiero | D2: valor inversion | E2: Período (n) | F2: Valor futuro (VF) | H2: tasa de descuento
A3: 1 | B3: =IFERROR(VLOOKUP(A3,Entradas_calculos!$B$2:$C$32,2,FALSE),0) -> 21007737 | D3: =(B3+C3) -> 21007737 | E3: =IF(A3>Entradas_calculos!$K$2,"",Entradas_calculos!$K$2-A3) -> 5 | F3: =IFERROR(D3*(1+$H$3)^E3,0) -> 31533644 | H3: =Entradas_Tasas!$F$57 -> 0.084623421
A4: 2 | B4: =IFERROR(VLOOKUP(A4,Entradas_calculos!$B$2:$C$32,2,FALSE),0) -> 16737024 | D4: =(B4+C4) -> 16737024 | E4: =IF(A4>Entradas_calculos!$K$2,"",Entradas_calculos!$K$2-A4) -> 4 | F4: =IFERROR(D4*(1+$H$3)^E4,0) -> 23162964
A5: 3 | B5: =IFERROR(VLOOKUP(A5,Entradas_calculos!$B$2:$C$32,2,FALSE),0) -> 16737024 | D5: =(B5+C5) -> 16737024 | E5: =IF(A5>Entradas_calculos!$K$2,"",Entradas_calculos!$K$2-A5) -> 3 | F5: =IFERROR(D5*(1+$H$3)^E5,0) -> 21355766
A6: 4 | B6: =IFERROR(VLOOKUP(A6,Entradas_calculos!$B$2:$C$32,2,FALSE),0) -> 16737024 | D6: =IFERROR(B6+C6,0) -> 16737024 | E6: =IF(A6>Entradas_calculos!$K$2,"",Entradas_calculos!$K$2-A6) -> 2 | F6: =IFERROR(D6*(1+$H$3)^E6,0) -> 19689568
A7: 5 | B7: =IFERROR(VLOOKUP(A7,Entradas_calculos!$B$2:$C$32,2,FALSE),0) -> 16737024 | D7: =IFERROR(B7+C7,0) -> 16737024 | E7: =IF(A7>Entradas_calculos!$K$2,"",Entradas_calculos!$K$2-A7) -> 1 | F7: =IFERROR(D7*(1+$H$3)^E7,0) -> 18153368
A8: 6 | B8: =IFERROR(VLOOKUP(A8,Entradas_calculos!$B$2:$C$32,2,FALSE),0) -> 18097824 | D8: =IFERROR(B8+C8,0) -> 18097824 | E8: =IF(A8>Entradas_calculos!$K$2,"",Entradas_calculos!$K$2-A8) -> 0 | F8: =IFERROR(D8*(1+$H$3)^E8,0) -> 18097824
A9: 7 | B9: =IFERROR(VLOOKUP(A9,Entradas_calculos!$B$2:$C$32,2,FALSE),0) | D9: =IFERROR(B9+C9,0) -> 0 | E9: =IF(A9>Entradas_calculos!$K$2,"",Entradas_calculos!$K$2-A9) | F9: =IFERROR(D9*(1+$H$3)^E9,0) -> 0
A10: 8 | B10: =IFERROR(VLOOKUP(A10,Entradas_calculos!$B$2:$C$32,2,FALSE),0) | D10: =IFERROR(B10+C10,0) -> 0 | E10: =IF(A10>Entradas_calculos!$K$2,"",Entradas_calculos!$K$2-A10) | F10: =IFERROR(D10*(1+$H$3)^E10,0) -> 0
A11: 9 | B11: =IFERROR(VLOOKUP(A11,Entradas_calculos!$B$2:$C$32,2,FALSE),0) | D11: =IFERROR(B11+C11,0) -> 0 | E11: =IF(A11>Entradas_calculos!$K$2,"",Entradas_calculos!$K$2-A11) | F11: =IFERROR(D11*(1+$H$3)^E11,0) -> 0
A12: 10 | B12: =IFERROR(VLOOKUP(A12,Entradas_calculos!$B$2:$C$32,2,FALSE),0) | D12: =IFERROR(B12+C12,0) -> 0 | E12: =IF(A12>Entradas_calculos!$K$2,"",Entradas_calculos!$K$2-A12) | F12: =IFERROR(D12*(1+$H$3)^E12,0) -> 0
A13: 11 | B13: =IFERROR(VLOOKUP(A13,Entradas_calculos!$B$2:$C$32,2,FALSE),0) | D13: =IFERROR(B13+C13,0) -> 0 | E13: =IF(A13>Entradas_calculos!$K$2,"",Entradas_calculos!$K$2-A13) | F13: =IFERROR(D13*(1+$H$3)^E13,0) -> 0
A14: 12 | B14: =IFERROR(VLOOKUP(A14,Entradas_calculos!$B$2:$C$32,2,FALSE),0) | D14: =IFERROR(B14+C14,0) -> 0 | E14: =IF(A14>Entradas_calculos!$K$2,"",Entradas_calculos!$K$2-A14) | F14: =IFERROR(D14*(1+$H$3)^E14,0) -> 0
A15: 13 | B15: =IFERROR(VLOOKUP(A15,Entradas_calculos!$B$2:$C$32,2,FALSE),0) | D15: =IFERROR(B15+C15,0) -> 0 | E15: =IF(A15>Entradas_calculos!$K$2,"",Entradas_calculos!$K$2-A15) | F15: =IFERROR(D15*(1+$H$3)^E15,0) -> 0
A16: 14 | B16: =IFERROR(VLOOKUP(A16,Entradas_calculos!$B$2:$C$32,2,FALSE),0) | D16: =IFERROR(B16+C16,0) -> 0 | E16: =IF(A16>Entradas_calculos!$K$2,"",Entradas_calculos!$K$2-A16) | F16: =IFERROR(D16*(1+$H$3)^E16,0) -> 0
A17: 15 | B17: =IFERROR(VLOOKUP(A17,Entradas_calculos!$B$2:$C$32,2,FALSE),0) | D17: =IFERROR(B17+C17,0) -> 0 | E17: =IF(A17>Entradas_calculos!$K$2,"",Entradas_calculos!$K$2-A17) | F17: =IFERROR(D17*(1+$H$3)^E17,0) -> 0
... A32: 30 | B32: =IFERROR(VLOOKUP(A32,Entradas_calculos!$B$2:$C$32,2,FALSE),0) -> 0 | D32: =IFERROR(B32+C32,0) -> 0 | E32: =IF(A32>Entradas_calculos!$K$2,"",Entradas_calculos!$K$2-A32) | F32: =IFERROR(D32*(1+$H$3)^E32,0) -> 0
D33: {=SUMPRODUCT(ISNUMBER(E3:E32)*D3:D32)} -> 1.0605365e+08 | F33: =SUM(F3:F32) -> 1.3199313e+08 | G33: =F33-D33 -> 25939479
G34: =G33/F33 -> 0.19652143

Sheet Calculo_etapa_productiva
A1: Edad | B1: Prod/ha (kg) | C1: Precio | D1: Ingreso (Prod*Precio) | E1: Costo/ha | F1: Costo Financiero | G1: Flujo Neto | H1: n (años) | I1: Interés | J1: Factor Descuento | K1: VP del Flujo | L1: VPN Remanente | M1: VPN traído al momento 0
A2: 1 | B2: =IFERROR(VLOOKUP(A2,Entradas_calculos!$E$3:$F$32,2,FALSE),0) -> 10450 | C2: =Entradas_calculos!$K$3 -> 4000 | D2: =IFERROR(B2*C2,0) -> 41800000 | E2: =IFERROR(VLOOKUP(A2,Entradas_calculos!$B$3:$C$32,2,FALSE),0) -> 21007737 | F2: =+IF(AND(A2<=Amortización!$B$3,A2-Amortización!$B$4>0),IFERROR(VLOOKUP(A2,Amortización!$A$8:$B$32,2,FALSE),0),0) -> 0 | G2: =IFERROR(D2-E2-F2,0) -> 20792263 | H2: =IF(A2<Entradas_calculos!$K$2,"",A2-Entradas_calculos!$K$2+1) | I2: =Entradas_calculos!$K$4 -> 0.084623421 | J2: =IF(H2="","",(1+I2)^H2) | K2: =IF(J2="",0,G2/J2) -> 0 | L2: =+NPV(Entradas_calculos!$K$4,G2:G31) -> 1.8336e+08
A3: 2 | B3: =IFERROR(VLOOKUP(A3,Entradas_calculos!$E$3:$F$32,2,FALSE),0) -> 17100 | C3: =Entradas_calculos!$K$3 -> 4000 | D3: =IFERROR(B3*C3,0) -> 68400000 | E3: =IFERROR(VLOOKUP(A3,Entradas_calculos!$B$3:$C$32,2,FALSE),0) -> 16737024 | F3: =+IF(AND(A3<=Amortización!$B$3,A3-Amortización!$B$4>0),IFERROR(VLOOKUP(A3,Amortización!$A$8:$B$32,2,FALSE),0),0) -> 0 | G3: =IFERROR(D3-E3-F3,0) -> 51662976 | H3: =IF(A3<Entradas_calculos!$K$2,"",A3-Entradas_calculos!$K$2+1) | I3: =Entradas_calculos!$K$4 -> 0.084623421 | J3: =IF(H3="","",(1+I3)^H3) | K3: =IF(J3="",0,G3/J3) -> 0 | L3: =+NPV(Entradas_calculos!$K$4,G3:G31) -> 1.7808428e+08
A4: 3 | B4: =IFERROR(VLOOKUP(A4,Entradas_calculos!$E$3:$F$32,2,FALSE),0) -> 16245 | C4: =Entradas_calculos!$K$3 -> 4000 | D4: =IFERROR(B4*C4,0) -> 64980000 | E4: =IFERROR(VLOOKUP(A4,Entradas_calculos!$B$3:$C$32,2,FALSE),0) -> 16737024 | F4: =+IF(AND(A4<=Amortización!$B$3,A4-Amortización!$B$4>0),IFERROR(VLOOKUP(A4,Amortización!$A$8:$B$32,2,FALSE),0),0) -> 0 | G4: =IFERROR(D4-E4-F4,0) -> 48242976 | H4: =IF(A4<Entradas_calculos!$K$2,"",A4-Entradas_calculos!$K$2+1) | I4: =Entradas_calculos!$K$4 -> 0.084623421 | J4: =IF(H4="","",(1+I4)^H4) | K4: =IF(J4="",0,G4/J4) -> 0 | L4: =+NPV(Entradas_calculos!$K$4,G4:G31) -> 1.4149141e+08 | M4: =IF(H4="","",L4/((1+Entradas_calculos!$K$4)^H4))
A5: 4 | B5: =IFERROR(VLOOKUP(A5,Entradas_calculos!$E$3:$F$32,2,FALSE),0) -> 15390 | C5: =Entradas_calculos!$K$3 -> 4000 | D5: =IFERROR(B5*C5,0) -> 61560000 | E5: =IFERROR(VLOOKUP(A5,Entradas_calculos!$B$3:$C$32,2,FALSE),0) -> 16737024 | F5: =+IF(AND(A5<=Amortización!$B$3,A5-Amortización!$B$4>0),IFERROR(VLOOKUP(A5,Amortización!$A$8:$B$32,2,FALSE),0),0) -> 0 | G5: =IFERROR(D5-E5-F5,0) -> 44822976 | H5: =IF(A5<Entradas_calculos!$K$2,"",A5-Entradas_calculos!$K$2+1) | I5: =Entradas_calculos!$K$4 -> 0.084623421 | J5: =IF(H5="","",(1+I5)^H5) | K5: =IF(J5="",0,G5/J5) -> 0 | L5: =+NPV(Entradas_calculos!$K$4,G5:G31) -> 1.0522192e+08 | M5: =IF(H5="","",L5/((1+Entradas_calculos!$K$4)^H5))
A6: 5 | B6: =IFERROR(VLOOKUP(A6,Entradas_calculos!$E$3:$F$32,2,FALSE),0) -> 14535 | C6: =Entradas_calculos!$K$3 -> 4000 | D6: =IFERROR(B6*C6,0) -> 58140000 | E6: =IFERROR(VLOOKUP(A6,Entradas_calculos!$B$3:$C$32,2,FALSE),0) -> 16737024 | F6: =+IF(AND(A6<=Amortización!$B$3,A6-Amortización!$B$4>0),IFERROR(VLOOKUP(A6,Amortización!$A$8:$B$32,2,FALSE),0),0) -> 0 | G6: =IFERROR(D6-E6-F6,0) -> 41402976 | H6: =IF(A6<Entradas_calculos!$K$2,"",A6-Entradas_calculos!$K$2+1) | I6: =Entradas_calculos!$K$4 -> 0.084623421 | J6: =IF(H6="","",(1+I6)^H6) | K6: =IF(J6="",0,G6/J6) -> 0 | L6: =+NPV(Entradas_calculos!$K$4,G6:G31) -> 69303181 | M6: =IF(H6="","",L6/((1+Entradas_calculos!$K$4)^H6))
A7: 6 | B7: =IFERROR(VLOOKUP(A7,Entradas_calculos!$E$3:$F$32,2,FALSE),0) -> 13680 | C7: =Entradas_calculos!$K$3 -> 4000 | D7: =IFERROR(B7*C7,0) -> 54720000 | E7: =IFERROR(VLOOKUP(A7,Entradas_calculos!$B$3:$C$32,2,FALSE),0) -> 18097824 | F7: =+IF(AND(A7<=Amortización!$B$3,A7-Amortización!$B$4>0),IFERROR(VLOOKUP(A7,Amortización!$A$8:$B$32,2,FALSE),0),0) -> 0 | G7: =IFERROR(D7-E7-F7,0) -> 36622176 | H7: =IF(A7<Entradas_calculos!$K$2,"",A7-Entradas_calculos!$K$2+1) -> 1 | I7: =Entradas_calculos!$K$4 -> 0.084623421 | J7: =IF(H7="","",(1+I7)^H7) -> 1.0846234 | K7: =IF(J7="",0,G7/J7) -> 33764877 | L7: =+NPV(Entradas_calculos!$K$4,G7:G31) -> 33764877 | M7: =IF(H7="","",L7/((1+Entradas_calculos!$K$4)^H7)) -> 31130507
